2022-08-26 23:50:07,547 - television - 80 - произошла ошибка: 
Traceback (most recent call last):
  File "/home/dok2412/PycharmProjects/botTVin/main.py", line 69, in television
    bot.send_message(message.from_user.id, "'Настройка и установка спутникового, цифрового"
  File "/home/dok2412/PycharmProjects/botTVin/venv/lib/python3.10/site-packages/telebot/__init__.py", line 1451, in send_message
    apihelper.send_message(
  File "/home/dok2412/PycharmProjects/botTVin/venv/lib/python3.10/site-packages/telebot/apihelper.py", line 263, in send_message
    payload['reply_markup'] = _convert_markup(reply_markup)
  File "/home/dok2412/PycharmProjects/botTVin/venv/lib/python3.10/site-packages/telebot/apihelper.py", line 1752, in _convert_markup
    return markup.to_json()
  File "/home/dok2412/PycharmProjects/botTVin/venv/lib/python3.10/site-packages/telebot/types.py", line 2259, in to_json
    return json.dumps(self.to_dict())
  File "/usr/lib/python3.10/json/__init__.py", line 231, in dumps
    return _default_encoder.encode(obj)
  File "/usr/lib/python3.10/json/encoder.py", line 199, in encode
    chunks = self.iterencode(o, _one_shot=True)
  File "/usr/lib/python3.10/json/encoder.py", line 257, in iterencode
    return _iterencode(o, 0)
  File "/usr/lib/python3.10/json/encoder.py", line 179, in default
    raise TypeError(f'Object of type {o.__class__.__name__} '
TypeError: Object of type function is not JSON serializable
2022-08-26 23:50:39,119 - start_handler - 56 - произошла ошибка: 
Traceback (most recent call last):
  File "/home/dok2412/PycharmProjects/botTVin/main.py", line 54, in start_handler
    bot.send_message(message.chat.id, 'TVin - телевидение и интерент.\nДобро пожаловать {0}!'.format(message.from_user.first_name), reply_markup=keyboard)
AttributeError: 'CallbackQuery' object has no attribute 'chat'
2022-08-26 23:50:39,406 - television - 80 - произошла ошибка: 
Traceback (most recent call last):
  File "/home/dok2412/PycharmProjects/botTVin/main.py", line 69, in television
    bot.send_message(message.from_user.id, "'Настройка и установка спутникового, цифрового"
  File "/home/dok2412/PycharmProjects/botTVin/venv/lib/python3.10/site-packages/telebot/__init__.py", line 1451, in send_message
    apihelper.send_message(
  File "/home/dok2412/PycharmProjects/botTVin/venv/lib/python3.10/site-packages/telebot/apihelper.py", line 276, in send_message
    return _make_request(token, method_url, params=payload, method='post')
  File "/home/dok2412/PycharmProjects/botTVin/venv/lib/python3.10/site-packages/telebot/apihelper.py", line 161, in _make_request
    json_result = _check_result(method_name, result)
  File "/home/dok2412/PycharmProjects/botTVin/venv/lib/python3.10/site-packages/telebot/apihelper.py", line 188, in _check_result
    raise ApiTelegramException(method_name, result, result_json)
telebot.apihelper.ApiTelegramException: A request to the Telegram API was unsuccessful. Error code: 400. Description: Bad Request: can't parse inline keyboard button: Text buttons are unallowed in the inline keyboard
2022-08-26 23:56:11,555 - meny - 254 - произошла ошибка: 
Traceback (most recent call last):
  File "/home/dok2412/PycharmProjects/botTVin/main.py", line 249, in meny
    bot.send_message(message.chat.id,
AttributeError: 'CallbackQuery' object has no attribute 'chat'
